<?xml version="1.0" ?>
<!-- =================================================================================== -->
<!-- |    This document was autogenerated by xacro from /home/bot/catkin_ws/src/phoebe_stack/phoebe_description/phoebe.urdf.xacro | -->
<!-- |    EDITING THIS FILE BY HAND IS NOT RECOMMENDED                                 | -->
<!-- =================================================================================== -->
<robot name="phoebe" xmlns:xacro="http://www.ros.org/wiki/xacro">
  <link name="base_link">
    <visual>
      <origin rpy="0 0 0" xyz="0 0 0"/>
      <geometry>
        <mesh filename="package://phoebe_description/meshes/phoebe.dae"/>
      </geometry>
    </visual>
    <collision>
      <origin rpy="0 0 0" xyz="0 0 0"/>
      <geometry>
        <mesh filename="package://phoebe_description/meshes/phoebe.dae"/>
      </geometry>
    </collision>
  </link>
  <joint name="wheel_left_joint" type="continuous">
    <parent link="base_link"/>
    <child link="wheel_left"/>
    <origin rpy="1.570796 0 0" xyz="0.0 0.18 0.095"/>
    <axis xyz="0 0 1"/>
  </joint>
  <link name="wheel_left">
    <visual>
      <origin rpy="0 0 0" xyz="0 0 0"/>
      <geometry>
        <cylinder length="0.05" radius="0.095"/>
      </geometry>
      <material name="blackish">
        <color rgba="0.2 0.2 0.2 1"/>
      </material>
    </visual>
    <collision>
      <origin rpy="0 0 0" xyz="0 0 0"/>
      <geometry>
        <cylinder length="0.05" radius="0.095"/>
      </geometry>
    </collision>
  </link>
  <joint name="wheel_right_joint" type="continuous">
    <parent link="base_link"/>
    <child link="wheel_right"/>
    <origin rpy="1.570796 0 0" xyz="0.0 -0.18 0.095"/>
    <axis xyz="0 0 1"/>
  </joint>
  <link name="wheel_right">
    <visual>
      <origin rpy="0 0 0" xyz="0 0 0"/>
      <geometry>
        <cylinder length="0.05" radius="0.095"/>
      </geometry>
      <material name="blackish"/>
    </visual>
    <collision>
      <origin rpy="0 0 0" xyz="0 0 0"/>
      <geometry>
        <cylinder length="0.05" radius="0.095"/>
      </geometry>
    </collision>
  </link>
  <!-- Cyton Gamma 1500 models -->
  <!-- Right arm -->
  <joint name="right_arm_joint" type="fixed">
    <parent link="base_link"/>
    <child link="right_arm_base_link"/>
    <origin rpy="1.5708 -1.5708 0" xyz="0.067 -0.162 0.8"/>
  </joint>
  <link name="right_arm_base_link">
    <visual>
      <origin rpy="0 0 0" xyz="0 0 0"/>
      <geometry>
        <mesh filename="package://cyton_gamma_1500_description/meshes/base.dae"/>
      </geometry>
    </visual>
    <collision>
      <origin xyz="0 0.0115 0.047"/>
      <geometry>
        <box size="0.154 0.177 0.094"/>
      </geometry>
    </collision>
  </link>
  <joint name="right_arm_shoulder_roll_joint" type="revolute">
    <parent link="right_arm_base_link"/>
    <child link="right_arm_shoulder_roll"/>
    <origin rpy="0 0 0" xyz="0 0 0.05315"/>
    <limit effort="100.0" lower="-2.618" upper="2.618" velocity="1.0"/>
    <axis xyz="0 0 1"/>
  </joint>
  <link name="right_arm_shoulder_roll">
    <visual>
      <origin rpy="1.5708 0 0.384" xyz="0 0 0"/>
      <geometry>
        <mesh filename="package://cyton_gamma_1500_description/meshes/shoulder_roll.dae"/>
      </geometry>
    </visual>
    <collision>
      <origin xyz="0.0 0.069 0.0587"/>
      <geometry>
        <box size="0.09829 0.18143 0.08392"/>
      </geometry>
    </collision>
  </link>
  <joint name="right_arm_shoulder_pitch_joint" type="revolute">
    <parent link="right_arm_shoulder_roll"/>
    <child link="right_arm_shoulder_pitch"/>
    <origin rpy="0 0 0" xyz="0.0205 0 0.12435"/>
    <limit effort="100.0" lower="-1.8326" upper="1.8326" velocity="1.0"/>
    <axis xyz="1 0 0"/>
  </joint>
  <link name="right_arm_shoulder_pitch">
    <visual>
      <origin rpy="1.5708 0 0" xyz="0 0 0"/>
      <geometry>
        <mesh filename="package://cyton_gamma_1500_description/meshes/shoulder_pitch.dae"/>
      </geometry>
    </visual>
    <collision>
      <origin xyz="-0.001 0.064 0.1745"/>
      <geometry>
        <box size="0.0709 0.19363 0.083"/>
      </geometry>
    </collision>
  </link>
  <joint name="right_arm_shoulder_yaw_joint" type="revolute">
    <parent link="right_arm_shoulder_pitch"/>
    <child link="right_arm_shoulder_yaw"/>
    <origin rpy="0 0 0" xyz="-0.0215 -0.0205 0.1255"/>
    <limit effort="100.0" lower="-1.8326" upper="1.8326" velocity="1.0"/>
    <axis xyz="0 -1 0"/>
  </joint>
  <link name="right_arm_shoulder_yaw">
    <visual>
      <origin rpy="1.5708 0 -1.5708" xyz="0 0 0.0"/>
      <geometry>
        <mesh filename="package://cyton_gamma_1500_description/meshes/shoulder_yaw.dae"/>
      </geometry>
    </visual>
    <collision>
      <origin xyz="-0.0225 0.039 0.3068"/>
      <geometry>
        <box size="0.0717 0.1846 0.0756"/>
      </geometry>
    </collision>
  </link>
  <joint name="right_arm_elbow_pitch_joint" type="revolute">
    <parent link="right_arm_shoulder_yaw"/>
    <child link="right_arm_elbow_pitch"/>
    <origin rpy="0 0 0" xyz="0.018 0.0206 0.1158"/>
    <limit effort="100.0" lower="-1.8326" upper="1.8326" velocity="1.0"/>
    <axis xyz="1 0 0"/>
  </joint>
  <link name="right_arm_elbow_pitch">
    <visual>
      <origin rpy="1.5708 0 3.1416" xyz="0 0 0"/>
      <geometry>
        <mesh filename="package://cyton_gamma_1500_description/meshes/elbow_pitch.dae"/>
      </geometry>
    </visual>
    <collision>
      <origin xyz="0.0346 0.0461 0.4228"/>
      <geometry>
        <box size="0.0549 0.1557 0.076"/>
      </geometry>
    </collision>
  </link>
  <joint name="right_arm_elbow_yaw_joint" type="revolute">
    <parent link="right_arm_elbow_pitch"/>
    <child link="right_arm_elbow_yaw"/>
    <origin rpy="0 0 0" xyz="-0.0171 -0.018 0.09746"/>
    <limit effort="100.0" lower="-1.8326" upper="1.8326" velocity="1.0"/>
    <axis xyz="0 -1 0"/>
  </joint>
  <link name="right_arm_elbow_yaw">
    <visual>
      <origin rpy="1.5708 0 1.5708" xyz="0 0 0"/>
      <geometry>
        <mesh filename="package://cyton_gamma_1500_description/meshes/elbow_yaw.dae"/>
      </geometry>
    </visual>
    <collision>
      <origin xyz="0.0172 0.0209 0.516"/>
      <geometry>
        <box size="0.0535 0.1160 0.0402"/>
      </geometry>
    </collision>
  </link>
  <joint name="right_arm_wrist_pitch_joint" type="revolute">
    <parent link="right_arm_elbow_yaw"/>
    <child link="right_arm_wrist_pitch"/>
    <origin rpy="0 0 0" xyz="0.02626 0.018 0.0718"/>
    <limit effort="100.0" lower="-1.8326" upper="1.8326" velocity="1.0"/>
    <axis xyz="-1 0 0"/>
  </joint>
  <link name="right_arm_wrist_pitch">
    <visual>
      <origin rpy="1.5708 0 1.5708" xyz="0 0 0"/>
      <geometry>
        <mesh filename="package://cyton_gamma_1500_description/meshes/wrist_pitch.dae"/>
      </geometry>
    </visual>
    <collision>
      <origin xyz="0.0257 0.0118 0.5617"/>
      <geometry>
        <box size="0.026 0.0435 0.05185"/>
      </geometry>
    </collision>
  </link>
  <joint name="right_arm_wrist_roll_joint" type="revolute">
    <parent link="right_arm_wrist_pitch"/>
    <child link="right_arm_wrist_roll"/>
    <origin rpy="0 0 0" xyz="-0.026255 0 0.051425"/>
    <limit effort="100.0" lower="-2.61799" upper="2.61799" velocity="1.0"/>
    <axis xyz="0 0 1"/>
  </joint>
  <link name="right_arm_wrist_roll">
    <visual>
      <origin rpy="3.1416 0 -1.5708" xyz="0 0 0"/>
      <geometry>
        <mesh filename="package://cyton_gamma_1500_description/meshes/wrist_roll.dae"/>
      </geometry>
    </visual>
    <collision>
      <origin xyz="-0.0063 -0.0014 0.6102"/>
      <geometry>
        <box size="0.0518 0.0723 0.1004"/>
      </geometry>
    </collision>
  </link>
  <joint name="right_arm_gripper_joint" type="prismatic">
    <parent link="right_arm_wrist_roll"/>
    <child link="right_arm_gripper_finger1"/>
    <origin rpy="0 0 0" xyz="-0.01331 0.00485 0.077225"/>
    <limit effort="100.0" lower="-0.008" upper="0.008" velocity="1.0"/>
    <axis xyz="1 0 0"/>
  </joint>
  <link name="right_arm_gripper_finger1">
    <visual>
      <origin rpy="0 0 0" xyz="0 0 0"/>
      <geometry>
        <mesh filename="package://cyton_gamma_1500_description/meshes/gripper_finger1.dae"/>
      </geometry>
    </visual>
    <collision>
      <origin xyz="-0.0167 0.0172 0.7254"/>
      <geometry>
        <box size="0.015 0.0229 0.0475"/>
      </geometry>
    </collision>
  </link>
  <joint name="right_arm_gripper_joint2" type="prismatic">
    <parent link="right_arm_wrist_roll"/>
    <child link="right_arm_gripper_finger2"/>
    <origin rpy="0 0 0" xyz="0.0098 0.00485 0.077225"/>
    <limit effort="100.0" lower="-0.008" upper="0.008" velocity="1.0"/>
    <mimic joint="right_arm_gripper_joint" multiplier="-1"/>
    <axis xyz="1 0 0"/>
  </joint>
  <link name="right_arm_gripper_finger2">
    <visual>
      <origin rpy="0 0 0" xyz="0 0 0"/>
      <geometry>
        <mesh filename="package://cyton_gamma_1500_description/meshes/gripper_finger2.dae"/>
      </geometry>
    </visual>
    <collision>
      <origin xyz="0.0132 0.0172 0.7254"/>
      <geometry>
        <box size="0.015 0.0229 0.0475"/>
      </geometry>
    </collision>
  </link>
  <!-- virtual end-effector -->
  <joint name="right_arm_virtual_endeffector_joint" type="fixed">
    <parent link="right_arm_wrist_roll"/>
    <child link="right_arm_virtual_endeffector"/>
    <origin rpy="0 0 0" xyz="-0.002316 0.0079 0.079425"/>
  </joint>
  <link name="right_arm_virtual_endeffector">
    <visual>
      <origin rpy="0 0 0" xyz="0 0 0"/>
      <geometry>
        <sphere radius="0.002"/>
      </geometry>
      <material name="grey">
        <color rgba="0.7 0.7 0.7 0.8"/>
      </material>
    </visual>
  </link>
  <joint name="right_arm_camera_bracket_joint" type="fixed">
    <parent link="right_arm_wrist_roll"/>
    <child link="right_arm_camera_bracket"/>
    <origin rpy="0 0 0" xyz="-0.0008 -0.028 0.0435"/>
  </joint>
  <link name="right_arm_camera_bracket">
    <visual>
      <origin rpy="0 0 0" xyz="0 0 0"/>
      <geometry>
        <mesh filename="package://cyton_gamma_1500_minicam_description/meshes/cam_bracket.dae"/>
      </geometry>
    </visual>
    <!--collision>
        <origin xyz="0.0 0.0 0.0"/>
        <geometry>
          <box size="0.03512 0.04821 0.07179"/>
        </geometry>
      </collision-->
  </link>
  <joint name="right_arm_camera_joint" type="fixed">
    <parent link="right_arm_camera_bracket"/>
    <child link="right_arm_camera"/>
    <origin rpy="-0.625 0 0" xyz="0.0 -0.028 -0.005"/>
  </joint>
  <link name="right_arm_camera">
    <visual>
      <origin rpy="0 0 0" xyz="0 0 0"/>
      <geometry>
        <box size="0.031 0.028 0.063"/>
      </geometry>
      <material name="blackish">
        <color rgba="0.2 0.2 0.2 1"/>
      </material>
    </visual>
    <collision>
      <origin rpy="0 0 0" xyz="0 0 0"/>
      <geometry>
        <box size="0.036 0.045 0.063"/>
      </geometry>
    </collision>
  </link>
  <!-- Left arm -->
  <joint name="left_arm_joint" type="fixed">
    <parent link="base_link"/>
    <child link="left_arm_base_link"/>
    <origin rpy="-1.5708 1.5708 0" xyz="0.067 0.162 0.8"/>
  </joint>
  <link name="left_arm_base_link">
    <visual>
      <origin rpy="0 0 0" xyz="0 0 0"/>
      <geometry>
        <mesh filename="package://cyton_gamma_1500_description/meshes/base.dae"/>
      </geometry>
    </visual>
    <collision>
      <origin xyz="0 0.0115 0.047"/>
      <geometry>
        <box size="0.154 0.177 0.094"/>
      </geometry>
    </collision>
  </link>
  <joint name="left_arm_shoulder_roll_joint" type="revolute">
    <parent link="left_arm_base_link"/>
    <child link="left_arm_shoulder_roll"/>
    <origin rpy="0 0 0" xyz="0 0 0.05315"/>
    <limit effort="100.0" lower="-2.618" upper="2.618" velocity="1.0"/>
    <axis xyz="0 0 1"/>
  </joint>
  <link name="left_arm_shoulder_roll">
    <visual>
      <origin rpy="1.5708 0 0.384" xyz="0 0 0"/>
      <geometry>
        <mesh filename="package://cyton_gamma_1500_description/meshes/shoulder_roll.dae"/>
      </geometry>
    </visual>
    <collision>
      <origin xyz="0.0 0.069 0.0587"/>
      <geometry>
        <box size="0.09829 0.18143 0.08392"/>
      </geometry>
    </collision>
  </link>
  <joint name="left_arm_shoulder_pitch_joint" type="revolute">
    <parent link="left_arm_shoulder_roll"/>
    <child link="left_arm_shoulder_pitch"/>
    <origin rpy="0 0 0" xyz="0.0205 0 0.12435"/>
    <limit effort="100.0" lower="-1.8326" upper="1.8326" velocity="1.0"/>
    <axis xyz="1 0 0"/>
  </joint>
  <link name="left_arm_shoulder_pitch">
    <visual>
      <origin rpy="1.5708 0 0" xyz="0 0 0"/>
      <geometry>
        <mesh filename="package://cyton_gamma_1500_description/meshes/shoulder_pitch.dae"/>
      </geometry>
    </visual>
    <collision>
      <origin xyz="-0.001 0.064 0.1745"/>
      <geometry>
        <box size="0.0709 0.19363 0.083"/>
      </geometry>
    </collision>
  </link>
  <joint name="left_arm_shoulder_yaw_joint" type="revolute">
    <parent link="left_arm_shoulder_pitch"/>
    <child link="left_arm_shoulder_yaw"/>
    <origin rpy="0 0 0" xyz="-0.0215 -0.0205 0.1255"/>
    <limit effort="100.0" lower="-1.8326" upper="1.8326" velocity="1.0"/>
    <axis xyz="0 -1 0"/>
  </joint>
  <link name="left_arm_shoulder_yaw">
    <visual>
      <origin rpy="1.5708 0 -1.5708" xyz="0 0 0.0"/>
      <geometry>
        <mesh filename="package://cyton_gamma_1500_description/meshes/shoulder_yaw.dae"/>
      </geometry>
    </visual>
    <collision>
      <origin xyz="-0.0225 0.039 0.3068"/>
      <geometry>
        <box size="0.0717 0.1846 0.0756"/>
      </geometry>
    </collision>
  </link>
  <joint name="left_arm_elbow_pitch_joint" type="revolute">
    <parent link="left_arm_shoulder_yaw"/>
    <child link="left_arm_elbow_pitch"/>
    <origin rpy="0 0 0" xyz="0.018 0.0206 0.1158"/>
    <limit effort="100.0" lower="-1.8326" upper="1.8326" velocity="1.0"/>
    <axis xyz="1 0 0"/>
  </joint>
  <link name="left_arm_elbow_pitch">
    <visual>
      <origin rpy="1.5708 0 3.1416" xyz="0 0 0"/>
      <geometry>
        <mesh filename="package://cyton_gamma_1500_description/meshes/elbow_pitch.dae"/>
      </geometry>
    </visual>
    <collision>
      <origin xyz="0.0346 0.0461 0.4228"/>
      <geometry>
        <box size="0.0549 0.1557 0.076"/>
      </geometry>
    </collision>
  </link>
  <joint name="left_arm_elbow_yaw_joint" type="revolute">
    <parent link="left_arm_elbow_pitch"/>
    <child link="left_arm_elbow_yaw"/>
    <origin rpy="0 0 0" xyz="-0.0171 -0.018 0.09746"/>
    <limit effort="100.0" lower="-1.8326" upper="1.8326" velocity="1.0"/>
    <axis xyz="0 -1 0"/>
  </joint>
  <link name="left_arm_elbow_yaw">
    <visual>
      <origin rpy="1.5708 0 1.5708" xyz="0 0 0"/>
      <geometry>
        <mesh filename="package://cyton_gamma_1500_description/meshes/elbow_yaw.dae"/>
      </geometry>
    </visual>
    <collision>
      <origin xyz="0.0172 0.0209 0.516"/>
      <geometry>
        <box size="0.0535 0.1160 0.0402"/>
      </geometry>
    </collision>
  </link>
  <joint name="left_arm_wrist_pitch_joint" type="revolute">
    <parent link="left_arm_elbow_yaw"/>
    <child link="left_arm_wrist_pitch"/>
    <origin rpy="0 0 0" xyz="0.02626 0.018 0.0718"/>
    <limit effort="100.0" lower="-1.8326" upper="1.8326" velocity="1.0"/>
    <axis xyz="-1 0 0"/>
  </joint>
  <link name="left_arm_wrist_pitch">
    <visual>
      <origin rpy="1.5708 0 1.5708" xyz="0 0 0"/>
      <geometry>
        <mesh filename="package://cyton_gamma_1500_description/meshes/wrist_pitch.dae"/>
      </geometry>
    </visual>
    <collision>
      <origin xyz="0.0257 0.0118 0.5617"/>
      <geometry>
        <box size="0.026 0.0435 0.05185"/>
      </geometry>
    </collision>
  </link>
  <joint name="left_arm_wrist_roll_joint" type="revolute">
    <parent link="left_arm_wrist_pitch"/>
    <child link="left_arm_wrist_roll"/>
    <origin rpy="0 0 0" xyz="-0.026255 0 0.051425"/>
    <limit effort="100.0" lower="-2.61799" upper="2.61799" velocity="1.0"/>
    <axis xyz="0 0 1"/>
  </joint>
  <link name="left_arm_wrist_roll">
    <visual>
      <origin rpy="3.1416 0 -1.5708" xyz="0 0 0"/>
      <geometry>
        <mesh filename="package://cyton_gamma_1500_description/meshes/wrist_roll.dae"/>
      </geometry>
    </visual>
    <collision>
      <origin xyz="-0.0063 -0.0014 0.6102"/>
      <geometry>
        <box size="0.0518 0.0723 0.1004"/>
      </geometry>
    </collision>
  </link>
  <joint name="left_arm_gripper_joint" type="prismatic">
    <parent link="left_arm_wrist_roll"/>
    <child link="left_arm_gripper_finger1"/>
    <origin rpy="0 0 0" xyz="-0.01331 0.00485 0.077225"/>
    <limit effort="100.0" lower="-0.008" upper="0.008" velocity="1.0"/>
    <axis xyz="1 0 0"/>
  </joint>
  <link name="left_arm_gripper_finger1">
    <visual>
      <origin rpy="0 0 0" xyz="0 0 0"/>
      <geometry>
        <mesh filename="package://cyton_gamma_1500_description/meshes/gripper_finger1.dae"/>
      </geometry>
    </visual>
    <collision>
      <origin xyz="-0.0167 0.0172 0.7254"/>
      <geometry>
        <box size="0.015 0.0229 0.0475"/>
      </geometry>
    </collision>
  </link>
  <joint name="left_arm_gripper_joint2" type="prismatic">
    <parent link="left_arm_wrist_roll"/>
    <child link="left_arm_gripper_finger2"/>
    <origin rpy="0 0 0" xyz="0.0098 0.00485 0.077225"/>
    <limit effort="100.0" lower="-0.008" upper="0.008" velocity="1.0"/>
    <mimic joint="left_arm_gripper_joint" multiplier="-1"/>
    <axis xyz="1 0 0"/>
  </joint>
  <link name="left_arm_gripper_finger2">
    <visual>
      <origin rpy="0 0 0" xyz="0 0 0"/>
      <geometry>
        <mesh filename="package://cyton_gamma_1500_description/meshes/gripper_finger2.dae"/>
      </geometry>
    </visual>
    <collision>
      <origin xyz="0.0132 0.0172 0.7254"/>
      <geometry>
        <box size="0.015 0.0229 0.0475"/>
      </geometry>
    </collision>
  </link>
  <!-- virtual end-effector -->
  <joint name="left_arm_virtual_endeffector_joint" type="fixed">
    <parent link="left_arm_wrist_roll"/>
    <child link="left_arm_virtual_endeffector"/>
    <origin rpy="0 0 0" xyz="-0.002316 0.0079 0.079425"/>
  </joint>
  <link name="left_arm_virtual_endeffector">
    <visual>
      <origin rpy="0 0 0" xyz="0 0 0"/>
      <geometry>
        <sphere radius="0.002"/>
      </geometry>
      <material name="grey">
        <color rgba="0.7 0.7 0.7 0.8"/>
      </material>
    </visual>
  </link>
  <joint name="left_arm_camera_bracket_joint" type="fixed">
    <parent link="left_arm_wrist_roll"/>
    <child link="left_arm_camera_bracket"/>
    <origin rpy="0 0 0" xyz="-0.0008 -0.028 0.0435"/>
  </joint>
  <link name="left_arm_camera_bracket">
    <visual>
      <origin rpy="0 0 0" xyz="0 0 0"/>
      <geometry>
        <mesh filename="package://cyton_gamma_1500_minicam_description/meshes/cam_bracket.dae"/>
      </geometry>
    </visual>
    <!--collision>
        <origin xyz="0.0 0.0 0.0"/>
        <geometry>
          <box size="0.03512 0.04821 0.07179"/>
        </geometry>
      </collision-->
  </link>
  <joint name="left_arm_camera_joint" type="fixed">
    <parent link="left_arm_camera_bracket"/>
    <child link="left_arm_camera"/>
    <origin rpy="-0.625 0 0" xyz="0.0 -0.028 -0.005"/>
  </joint>
  <link name="left_arm_camera">
    <visual>
      <origin rpy="0 0 0" xyz="0 0 0"/>
      <geometry>
        <box size="0.031 0.028 0.063"/>
      </geometry>
      <material name="blackish">
        <color rgba="0.2 0.2 0.2 1"/>
      </material>
    </visual>
    <collision>
      <origin rpy="0 0 0" xyz="0 0 0"/>
      <geometry>
        <box size="0.036 0.045 0.063"/>
      </geometry>
    </collision>
  </link>
  <!-- PTU -->
  <joint name="ptu_joint" type="fixed">
    <parent link="base_link"/>
    <child link="ptu_base_plate_link"/>
    <origin rpy="0 0 0" xyz="0.02 0 1.1075"/>
  </joint>
  <link name="ptu_base_plate_link">
    <visual>
      <origin rpy="0 0 0" xyz="-0.035 0 0.0025"/>
      <geometry>
        <box size="0.17 0.142 0.005"/>
      </geometry>
      <material name="black">
        <color rgba="0.2 0.2 0.2 1"/>
      </material>
    </visual>
  </link>
  <joint name="ptu_base_plate_joint" type="fixed">
    <parent link="ptu_base_plate_link"/>
    <child link="ptu_base_link"/>
    <origin rpy="0 0 0" xyz="0.0 0.0 0.0"/>
  </joint>
  <link name="ptu_base_link">
    </link>
  <joint name="ptu_base_joint" type="fixed">
    <parent link="ptu_base_link"/>
    <child link="ptu_pan_link"/>
    <origin rpy="0 0 0" xyz="0.0 0 0.005"/>
  </joint>
  <link name="ptu_pan_link">
    <visual>
      <origin rpy="0 0 0" xyz="0 0.0 0.025"/>
      <geometry>
        <mesh filename="package://dp_ptu_46_description/meshes/pan.dae"/>
      </geometry>
    </visual>
    <collision>
      <origin xyz="0 0.0115 0.047"/>
      <geometry>
        <box size="0.154 0.177 0.094"/>
      </geometry>
    </collision>
  </link>
  <joint name="ptu_pan_joint" type="revolute">
    <parent link="ptu_base_link"/>
    <child link="ptu_tilt_link"/>
    <origin rpy="0 0 0" xyz="-0.00436 -0.0067 0.03"/>
    <limit effort="100.0" lower="-2.775" upper="2.775" velocity="1.0"/>
    <axis xyz="0 0 1"/>
  </joint>
  <link name="ptu_tilt_link">
    <visual>
      <origin rpy="0 0 0" xyz="0.00436 0.0067 0.0"/>
      <geometry>
        <mesh filename="package://dp_ptu_46_description/meshes/tilt.dae"/>
      </geometry>
    </visual>
    <collision>
      <origin xyz="0 0.0115 0.047"/>
      <geometry>
        <box size="0.154 0.177 0.094"/>
      </geometry>
    </collision>
  </link>
  <joint name="ptu_tilt_joint" type="revolute">
    <parent link="ptu_tilt_link"/>
    <child link="ptu_mount_link"/>
    <origin rpy="0 0 0" xyz="0.0 0 0.0659"/>
    <limit effort="100.0" lower="-1.396" upper="0.541" velocity="1.0"/>
    <axis xyz="0 -1 0"/>
  </joint>
  <link name="ptu_mount_link">
    <visual>
      <origin rpy="0 0 0" xyz="0.00436 0.0067 -0.0659"/>
      <geometry>
        <mesh filename="package://dp_ptu_46_description/meshes/mount.dae"/>
      </geometry>
    </visual>
    <collision>
      <origin xyz="0 0.0115 0.047"/>
      <geometry>
        <box size="0.154 0.177 0.094"/>
      </geometry>
    </collision>
  </link>
  <!-- Hokuyo lidar -->
  <joint name="hokuyo_base_joint" type="fixed">
    <parent link="base_link"/>
    <child link="hokuyo_link"/>
    <origin rpy="0 0 0" xyz="0.1 0 0.3"/>
  </joint>
  <link name="hokuyo_link">
    <visual>
      <origin rpy="0 0 0" xyz="0 0 0"/>
      <geometry>
        <cylinder length="0.0265" radius="0.021"/>
      </geometry>
      <material name="blackish"/>
    </visual>
    <visual>
      <origin rpy="0 0 0" xyz="0 0 -0.034"/>
      <geometry>
        <box size="0.05 0.05 0.041"/>
      </geometry>
      <material name="blackish"/>
    </visual>
    <collision>
      <origin rpy="0 0 0" xyz="0 0 0"/>
      <geometry>
        <cylinder length="0.0265" radius="0.021"/>
      </geometry>
    </collision>
    <collision>
      <origin rpy="0 0 0" xyz="0 0 -0.047"/>
      <geometry>
        <box size="0.05 0.05 0.041"/>
      </geometry>
    </collision>
  </link>
  <!-- Bumblebee 2 -->
  <joint name="bumblebee_joint" type="fixed">
    <parent link="ptu_mount_link"/>
    <child link="bumblebee_link"/>
    <origin rpy="0 0 0" xyz="0 0 0.058"/>
  </joint>
  <link name="bumblebee_link">
    <visual>
      <origin rpy="0 0 0" xyz="0 0 0"/>
      <geometry>
        <box size="0.047 0.157 0.038"/>
      </geometry>
      <material name="golden">
        <color rgba="0.4 0.4 0.1 1"/>
      </material>
    </visual>
  </link>
  <joint name="bumblebee_cameras_joint" type="fixed">
    <parent link="bumblebee_link"/>
    <child link="bumblebee_cameras_link"/>
    <origin rpy="0 0 0" xyz="0 0 0.0"/>
  </joint>
  <link name="bumblebee_cameras_link">
    <visual>
      <origin rpy="0 1.5708 0" xyz="0.024 0.06 0"/>
      <geometry>
        <cylinder length="0.001" radius="0.011"/>
      </geometry>
      <material name="glass">
        <color rgba="1 1 1 0.2"/>
      </material>
    </visual>
    <visual>
      <origin rpy="0 1.5708 0" xyz="0.024 -0.06 0"/>
      <geometry>
        <cylinder length="0.001" radius="0.011"/>
      </geometry>
      <material name="glass"/>
    </visual>
  </link>
  <!-- Asus Xtion Pro Live -->
  <joint name="xtion_joint" type="fixed">
    <parent link="bumblebee_link"/>
    <child link="xtion_link"/>
    <origin rpy="0 0 0" xyz="0 0 0.055"/>
  </joint>
  <link name="xtion_link">
    <visual>
      <origin rpy="0 0 0" xyz="0 0 0"/>
      <geometry>
        <box size="0.036 0.178 0.03"/>
      </geometry>
      <material name="blackish"/>
    </visual>
    <visual>
      <origin rpy="0 0 0" xyz="0 0 -0.025"/>
      <geometry>
        <box size="0.02 0.017 0.02"/>
      </geometry>
      <material name="blackish"/>
    </visual>
    <visual>
      <origin rpy="0 0 0" xyz="0 0 -0.035"/>
      <geometry>
        <box size="0.04 0.1 0.004"/>
      </geometry>
      <material name="blackish"/>
    </visual>
  </link>
</robot>
