<?xml version="1.0"?>
<robot xmlns:xacro="http://www.ros.org/wiki/xacro" name="phoebe">
  <xacro:include filename="$(find cyton_gamma_1500_minicam_description)/cyton_gamma_1500_minicam_macros.urdf.xacro" />
  <xacro:include filename="$(find dp_ptu_46_description)/dp_ptu_46_macros.urdf.xacro" />

  <link name="base_link">
    <visual>
      <origin xyz="0 0 0" rpy="0 0 0"/>
      <geometry>
        <mesh filename="package://phoebe_description/meshes/phoebe.dae"/>
      </geometry>
    </visual>
    <collision>
      <origin xyz="0 0 0" rpy="0 0 0"/>
      <geometry>
        <mesh filename="package://phoebe_description/meshes/phoebe.dae"/>
      </geometry>
    </collision>
  </link>

  <joint name="wheel_left_joint" type="continuous">
    <parent link="base_link" />
    <child link="wheel_left" />
    <origin xyz="0.0 0.18 0.095" rpy="1.570796 0 0" />
    <axis xyz="0 0 1" />
  </joint>

  <link name="wheel_left">
    <visual>
      <origin xyz="0 0 0" rpy="0 0 0"/>
      <geometry>
        <cylinder radius="0.095" length="0.05" />
      </geometry>
      <material name="blackish">
        <color rgba="0.2 0.2 0.2 1"/>
      </material>
    </visual>
    <collision>
      <origin xyz="0 0 0" rpy="0 0 0"/>
      <geometry>
        <cylinder radius="0.095" length="0.05" />
      </geometry>
    </collision>
  </link>

  <joint name="wheel_right_joint" type="continuous">
    <parent link="base_link" />
    <child link="wheel_right" />
    <origin xyz="0.0 -0.18 0.095" rpy="1.570796 0 0" />
    <axis xyz="0 0 1" />
  </joint>

  <link name="wheel_right">
    <visual>
      <origin xyz="0 0 0" rpy="0 0 0"/>
      <geometry>
        <cylinder radius="0.095" length="0.05" />
      </geometry>
      <material name="blackish" />
    </visual>
    <collision>
      <origin xyz="0 0 0" rpy="0 0 0"/>
      <geometry>
        <cylinder radius="0.095" length="0.05" />
      </geometry>
    </collision>
  </link>

  <!-- Cyton Gamma 1500 models -->
  <!-- Right arm -->
  <joint name="right_arm_joint" type="fixed">
    <parent link="base_link" />
    <child link="right_arm_base_link" />
    <origin xyz="0.067 -0.162 0.8" rpy="1.5708 -1.5708 0" />
  </joint>
  <xacro:cyton_gamma_1500_minicam prefix="right_arm_" virtual_ee="true"/>

  <!-- Left arm -->
  <joint name="left_arm_joint" type="fixed">
    <parent link="base_link" />
    <child link="left_arm_base_link" />
    <origin xyz="0.067 0.162 0.8" rpy="-1.5708 1.5708 0" />
  </joint>
  <xacro:cyton_gamma_1500_minicam prefix="left_arm_" virtual_ee="true" />

  <!-- PTU -->
  <joint name="ptu_joint" type="fixed">
    <parent link="base_link" />
    <child link="ptu_base_plate_link" />
    <origin xyz="0.02 0 1.1075" rpy="0 0 0" />
  </joint>
  <xacro:dp_ptu_46 prefix="" plate="true" thickness="0.005" />

  <!-- Hokuyo lidar -->
  <joint name="hokuyo_base_joint" type="fixed">
    <parent link="base_link" />
    <child link="hokuyo_link" />
    <origin xyz="0.1 0 0.3" rpy="0 0 0" />
  </joint>

  <link name="hokuyo_link">
    <visual>
      <origin xyz="0 0 0" rpy="0 0 0"/>
      <geometry>
        <cylinder length="0.0265" radius="0.021" />
      </geometry>
      <material name="blackish" />
    </visual>
    <visual>
      <origin xyz="0 0 -0.034" rpy="0 0 0"/>
      <geometry>
        <box size="0.05 0.05 0.041"/>
      </geometry>
      <material name="blackish" />
    </visual>
    <collision>
      <origin xyz="0 0 0" rpy="0 0 0"/>
      <geometry>
        <cylinder length="0.0265" radius="0.021" />
      </geometry>
    </collision>
    <collision>
      <origin xyz="0 0 -0.047" rpy="0 0 0"/>
      <geometry>
        <box size="0.05 0.05 0.041"/>
      </geometry>
    </collision>
  </link>

  <!-- Bumblebee 2 -->
  <joint name="bumblebee_joint" type="fixed">
    <parent link="ptu_mount_link" />
    <child link="bumblebee_link" />
    <origin xyz="0 0 0.058" rpy="0 0 0" />
  </joint>

  <link name="bumblebee_link">
    <visual>
      <origin xyz="0 0 0" rpy="0 0 0"/>
      <geometry>
        <box size="0.047 0.157 0.038"/>
      </geometry>
      <material name="golden">
        <color rgba="0.4 0.4 0.1 1" />
      </material>
    </visual>
  </link>

  <joint name="bumblebee_cameras_joint" type="fixed">
    <parent link="bumblebee_link" />
    <child link="bumblebee_cameras_link" />
    <origin xyz="0 0 0.0" rpy="0 0 0" />
  </joint>

  <link name="bumblebee_cameras_link">
    <visual>
      <origin xyz="0.024 0.06 0" rpy="0 1.5708 0"/>
      <geometry>
        <cylinder length="0.001" radius="0.011" />
      </geometry>
      <material name="glass">
        <color rgba="1 1 1 0.2" />
      </material>
    </visual>
    <visual>
      <origin xyz="0.024 -0.06 0" rpy="0 1.5708 0"/>
      <geometry>
        <cylinder length="0.001" radius="0.011" />
      </geometry>
      <material name="glass" />
    </visual>
  </link>
  
  <!-- Asus Xtion Pro Live -->
  <joint name="xtion_joint" type="fixed">
    <parent link="bumblebee_link" />
    <child link="xtion_link" />
    <origin xyz="0 0 0.055" rpy="0 0 0" />
  </joint>

  <link name="xtion_link">
    <visual>
      <origin xyz="0 0 0" rpy="0 0 0"/>
      <geometry>
        <box size="0.036 0.178 0.03"/>
      </geometry>
      <material name="blackish" />
    </visual>
    <visual>
      <origin xyz="0 0 -0.025" rpy="0 0 0"/>
      <geometry>
        <box size="0.02 0.017 0.02"/>
      </geometry>
      <material name="blackish" />
    </visual>
    <visual>
      <origin xyz="0 0 -0.035" rpy="0 0 0"/>
      <geometry>
        <box size="0.04 0.1 0.004"/>
      </geometry>
      <material name="blackish" />
    </visual>
  </link>

</robot>
